{"timestamp": "2025-07-10T19:13:38.987009", "trace": "Traceback (most recent call last):\n      File \"main.py\", line 10, in <module>\n        result = divide(5, 0)\n      File \"main.py\", line 6, in divide\n        return a / b\n    ZeroDivisionError: division by zero", "result": {"parsedTrace": [{"file": "main.py", "line": 10, "function": "<module>", "code": "result = divide(5, 0)"}, {"file": "main.py", "line": 6, "function": "divide", "code": "return a / b"}], "error": {"errorType": "ZeroDivisionError", "message": "division by zero"}, "relatedErrors": [{"snippet": "Traceback (most recent call last):\n    File \"main.py\", line 10, in <module>\n        result = divide(5, 0)\n    File \"main.py\", line 6, in divide\n        return a / b\n    ZeroDivisionError: division by zero", "sourceType": "python_docs", "url": "https://docs.python.org/3/library/exceptions.html#ZeroDivisionError"}, {"snippet": "Traceback (most recent call last):\n    File \"main.py\", line 8, in <module>\n        value = d['missing']\n    KeyError: 'missing'", "sourceType": "python_docs", "url": "https://docs.python.org/3/library/exceptions.html#KeyError"}, {"snippet": "Traceback (most recent call last):\n    File \"main.py\", line 12, in <module>\n        item = my_list[10]\n    IndexError: list index out of range", "sourceType": "user_past_error", "url": ""}], "fixSuggestion": {"summary": "ZeroDivisionError: division by zero", "codeExample": "def divide(a, b):\n    if b == 0:\n        raise ZeroDivisionError('division by zero')\n    return a / b\nresult = divide(5, 0)", "references": [{"snippet": "Avoid division by zero.", "sourceType": "Python Documentation", "url": "https://docs.python.org/3/library/exceptions.html#ZeroDivisionError"}]}}}
{"timestamp": "2025-07-13T14:09:25.462950", "trace": "Traceback (most recent call last):\n      File \"main.py\", line 10, in <module>\n        result = divide(5, 0)\n      File \"main.py\", line 6, in divide\n        return a / b\n    ZeroDivisionError: division by zero", "result": {"parsedTrace": [{"file": "main.py", "line": 10, "function": "<module>", "code": "result = divide(5, 0)"}, {"file": "main.py", "line": 6, "function": "divide", "code": "return a / b"}], "error": {"errorType": "ZeroDivisionError", "message": "division by zero"}, "relatedErrors": [{"snippet": "Traceback (most recent call last):\n    File \"main.py\", line 10, in <module>\n        result = divide(5, 0)\n    File \"main.py\", line 6, in divide\n        return a / b\n    ZeroDivisionError: division by zero", "sourceType": "python_docs", "url": "https://docs.python.org/3/library/exceptions.html#ZeroDivisionError"}, {"snippet": "Traceback (most recent call last):\n    File \"main.py\", line 8, in <module>\n        value = d['missing']\n    KeyError: 'missing'", "sourceType": "python_docs", "url": "https://docs.python.org/3/library/exceptions.html#KeyError"}, {"snippet": "Traceback (most recent call last):\n    File \"main.py\", line 12, in <module>\n        item = my_list[10]\n    IndexError: list index out of range", "sourceType": "user_past_error", "url": ""}], "fixSuggestion": {"summary": "An error occurred while processing the fix suggestion.", "codeExample": "", "references": [], "error": "RetryError[<Future at 0x221e7da4f50 state=finished raised ValueError>]"}}}
{"timestamp": "2025-07-14T21:32:05.238762", "trace": "Traceback (most recent call last):\n      File \"main.py\", line 10, in <module>\n        result = divide(5, 0)\n      File \"main.py\", line 6, in divide\n        return a / b\n    ZeroDivisionError: division by zero", "result": {"parsedTrace": [{"file": "main.py", "line": 10, "function": "<module>", "code": "result = divide(5, 0)"}, {"file": "main.py", "line": 6, "function": "divide", "code": "return a / b"}], "error": {"errorType": "ZeroDivisionError", "message": "division by zero"}, "relatedErrors": [{"snippet": "Traceback (most recent call last):\n    File \"main.py\", line 10, in <module>\n        result = divide(5, 0)\n    File \"main.py\", line 6, in divide\n        return a / b\n    ZeroDivisionError: division by zero", "sourceType": "python_docs", "url": "https://docs.python.org/3/library/exceptions.html#ZeroDivisionError"}, {"snippet": "Traceback (most recent call last):\n    File \"main.py\", line 8, in <module>\n        value = d['missing']\n    KeyError: 'missing'", "sourceType": "python_docs", "url": "https://docs.python.org/3/library/exceptions.html#KeyError"}, {"snippet": "Traceback (most recent call last):\n    File \"main.py\", line 12, in <module>\n        item = my_list[10]\n    IndexError: list index out of range", "sourceType": "user_past_error", "url": ""}], "fixSuggestion": {"summary": "An error occurred while processing the fix suggestion.", "codeExample": "", "references": [], "error": "RetryError[<Future at 0x1c1530ec7d0 state=finished raised ValueError>]"}}}
{"timestamp": "2025-07-14T21:39:54.140095+00:00", "trace": "Traceback (most recent call last):\n      File \"main.py\", line 10, in <module>\n        result = divide(5, 0)\n      File \"main.py\", line 6, in divide\n        return a / b\n    ZeroDivisionError: division by zero", "result": {"parsedTrace": [{"file": "main.py", "line": 10, "function": "<module>", "code": "result = divide(5, 0)"}, {"file": "main.py", "line": 6, "function": "divide", "code": "return a / b"}], "error": {"errorType": "ZeroDivisionError", "message": "division by zero"}, "relatedErrors": [{"snippet": "Traceback (most recent call last):\n    File \"main.py\", line 10, in <module>\n        result = divide(5, 0)\n    File \"main.py\", line 6, in divide\n        return a / b\n    ZeroDivisionError: division by zero", "sourceType": "python_docs", "url": "https://docs.python.org/3/library/exceptions.html#ZeroDivisionError"}, {"snippet": "Traceback (most recent call last):\n    File \"main.py\", line 8, in <module>\n        value = d['missing']\n    KeyError: 'missing'", "sourceType": "python_docs", "url": "https://docs.python.org/3/library/exceptions.html#KeyError"}, {"snippet": "Traceback (most recent call last):\n    File \"main.py\", line 12, in <module>\n        item = my_list[10]\n    IndexError: list index out of range", "sourceType": "user_past_error", "url": ""}], "fixSuggestion": {"summary": "ZeroDivisionError: division by zero", "codeExample": "def divide(a, b):\n    if b == 0:\n        return 'Error: Division by zero is not allowed.'\n    else:\n        return a / b\n\nresult = divide(5, 0)", "references": [{"snippet": "Avoid division by zero in Python.", "sourceType": "documentation", "url": "https://docs.python.org/3/library/exceptions.html#ZeroDivisionError"}]}}}
{"timestamp": "2025-07-20T18:45:59.819078+00:00", "trace": "Traceback (most recent call last):\n  File \"test.py\", line 5, in <module>\n    result = 10 / 0\nZeroDivisionError: division by zero", "result": {"parsedTrace": [{"file": "test.py", "line": 5, "function": "<module>", "code": "result = 10 / 0"}], "error": {"errorType": "ZeroDivisionError", "message": "division by zero"}, "relatedErrors": [{"snippet": "Traceback (most recent call last):\n    File \"main.py\", line 10, in <module>\n        result = divide(5, 0)\n    File \"main.py\", line 6, in divide\n        return a / b\n    ZeroDivisionError: division by zero", "sourceType": "python_docs", "url": "https://docs.python.org/3/library/exceptions.html#ZeroDivisionError"}, {"snippet": "Traceback (most recent call last):\n    File \"main.py\", line 8, in <module>\n        value = d['missing']\n    KeyError: 'missing'", "sourceType": "python_docs", "url": "https://docs.python.org/3/library/exceptions.html#KeyError"}, {"snippet": "Traceback (most recent call last):\n    File \"main.py\", line 12, in <module>\n        item = my_list[10]\n    IndexError: list index out of range", "sourceType": "user_past_error", "url": ""}], "fixSuggestion": {"summary": "ZeroDivisionError: division by zero", "codeExample": "def divide(a, b):\n   if b == 0:\n       raise ZeroDivisionError('division by zero')\n   return a / b\n\nresult = divide(5, 0)", "references": [{"snippet": "Avoid division by zero.", "sourceType": "documentation", "url": "https://docs.python.org/3/library/exceptions.html#ZeroDivisionError"}]}}}
{"timestamp": "2025-07-21T21:41:35.093083+00:00", "trace": "Traceback (most recent call last):\n  File \"calculator.py\", line 15, in <module>\n    result = divide(10, 0)\n  File \"calculator.py\", line 5, in divide\n    return a / b\nZeroDivisionError: division by zero", "result": {"parsedTrace": [{"file": "calculator.py", "line": 15, "function": "<module>", "code": "result = divide(10, 0)"}, {"file": "calculator.py", "line": 5, "function": "divide", "code": "return a / b"}], "error": {"errorType": "ZeroDivisionError", "message": "division by zero"}, "relatedErrors": [{"snippet": "Traceback (most recent call last):\n    File \"main.py\", line 10, in <module>\n        result = divide(5, 0)\n    File \"main.py\", line 6, in divide\n        return a / b\n    ZeroDivisionError: division by zero", "sourceType": "python_docs", "url": "https://docs.python.org/3/library/exceptions.html#ZeroDivisionError"}, {"snippet": "Traceback (most recent call last):\n    File \"main.py\", line 8, in <module>\n        value = d['missing']\n    KeyError: 'missing'", "sourceType": "python_docs", "url": "https://docs.python.org/3/library/exceptions.html#KeyError"}, {"snippet": "Traceback (most recent call last):\n    File \"main.py\", line 12, in <module>\n        item = my_list[10]\n    IndexError: list index out of range", "sourceType": "user_past_error", "url": ""}], "fixSuggestion": {"summary": "An error occurred while processing the fix suggestion.", "codeExample": "", "references": [], "error": "RetryError[<Future at 0x204d3a39950 state=finished raised ResponseError>]"}}}
