{"timestamp": "2025-07-14T21:52:31.720957+00:00", "trace": "Traceback (most recent call last):\n      File \"main.py\", line 10, in <module>\n        result = divide(5, 0)\n      File \"main.py\", line 6, in divide\n        return a / b\n    ZeroDivisionError: division by zero", "result": {"parsedTrace": [{"file": "main.py", "line": 10, "function": "<module>", "code": "result = divide(5, 0)"}, {"file": "main.py", "line": 6, "function": "divide", "code": "return a / b"}], "error": {"errorType": "ZeroDivisionError", "message": "division by zero"}, "relatedErrors": [{"snippet": "Traceback (most recent call last):\n    File \"main.py\", line 10, in <module>\n        result = divide(5, 0)\n    File \"main.py\", line 6, in divide\n        return a / b\n    ZeroDivisionError: division by zero", "sourceType": "python_docs", "url": "https://docs.python.org/3/library/exceptions.html#ZeroDivisionError"}, {"snippet": "Traceback (most recent call last):\n    File \"main.py\", line 8, in <module>\n        value = d['missing']\n    KeyError: 'missing'", "sourceType": "python_docs", "url": "https://docs.python.org/3/library/exceptions.html#KeyError"}, {"snippet": "Traceback (most recent call last):\n    File \"main.py\", line 12, in <module>\n        item = my_list[10]\n    IndexError: list index out of range", "sourceType": "user_past_error", "url": ""}], "fixSuggestion": {"summary": "ZeroDivisionError: division by zero", "codeExample": "def divide(a, b):\n    if b == 0:\n        return 'Error: Division by zero is not allowed.'\n    else:\n        return a / b\n\nresult = divide(5, 0)\nprint(result) # Output: Error: Division by zero is not allowed.", "references": [{"snippet": "Avoid division by zero in Python", "sourceType": "article", "url": "https://realpython.com/avoid-division-by-zero/"}]}}}
{"timestamp": "2025-07-14T21:55:24.267548+00:00", "trace": "Traceback (most recent call last):\n      File \"main.py\", line 10, in <module>\n        result = divide(5, 0)\n      File \"main.py\", line 6, in divide\n        return a / b\n    ZeroDivisionError: division by zero", "result": {"parsedTrace": [{"file": "main.py", "line": 10, "function": "<module>", "code": "result = divide(5, 0)"}, {"file": "main.py", "line": 6, "function": "divide", "code": "return a / b"}], "error": {"errorType": "ZeroDivisionError", "message": "division by zero"}, "relatedErrors": [{"snippet": "Traceback (most recent call last):\n    File \"main.py\", line 10, in <module>\n        result = divide(5, 0)\n    File \"main.py\", line 6, in divide\n        return a / b\n    ZeroDivisionError: division by zero", "sourceType": "python_docs", "url": "https://docs.python.org/3/library/exceptions.html#ZeroDivisionError"}, {"snippet": "Traceback (most recent call last):\n    File \"main.py\", line 8, in <module>\n        value = d['missing']\n    KeyError: 'missing'", "sourceType": "python_docs", "url": "https://docs.python.org/3/library/exceptions.html#KeyError"}, {"snippet": "Traceback (most recent call last):\n    File \"main.py\", line 12, in <module>\n        item = my_list[10]\n    IndexError: list index out of range", "sourceType": "user_past_error", "url": ""}], "fixSuggestion": {"summary": "ZeroDivisionError: division by zero", "codeExample": "def divide(a, b):\n    if b == 0:\n        raise ZeroDivisionError('division by zero')\n    return a / b\nresult = divide(5, 0)", "references": [{"snippet": "Check for division by zero before performing the operation.", "sourceType": "Python Documentation", "url": "https://docs.python.org/3/library/exceptions.html#ZeroDivisionError"}]}}}
{"timestamp": "2025-07-20T13:28:58.278060+00:00", "trace": "Traceback (most recent call last):\n          File \"main.py\", line 10, in <module>\n            result = divide(5, 0)\n          File \"main.py\", line 6, in divide\n            return a / b\n        ZeroDivisionError: division by zero", "result": {"parsedTrace": [{"file": "main.py", "line": 10, "function": "<module>", "code": "result = divide(5, 0)"}, {"file": "main.py", "line": 6, "function": "divide", "code": "return a / b"}], "error": {"errorType": "ZeroDivisionError", "message": "division by zero"}, "relatedErrors": [{"snippet": "Traceback (most recent call last):\n    File \"main.py\", line 10, in <module>\n        result = divide(5, 0)\n    File \"main.py\", line 6, in divide\n        return a / b\n    ZeroDivisionError: division by zero", "sourceType": "python_docs", "url": "https://docs.python.org/3/library/exceptions.html#ZeroDivisionError"}, {"snippet": "Traceback (most recent call last):\n    File \"main.py\", line 8, in <module>\n        value = d['missing']\n    KeyError: 'missing'", "sourceType": "python_docs", "url": "https://docs.python.org/3/library/exceptions.html#KeyError"}, {"snippet": "Traceback (most recent call last):\n    File \"main.py\", line 12, in <module>\n        item = my_list[10]\n    IndexError: list index out of range", "sourceType": "user_past_error", "url": ""}], "fixSuggestion": {"summary": "An error occurred while processing the fix suggestion.", "codeExample": "", "references": [], "error": "RetryError[<Future at 0x1c8cd7fa0d0 state=finished raised ResponseError>]"}}}
{"timestamp": "2025-07-20T13:34:20.473199+00:00", "trace": "Traceback (most recent call last):\n  File \"test.py\", line 1, in <module>\n    print(1/0)\nZeroDivisionError: division by zero", "result": {"parsedTrace": [{"file": "test.py", "line": 1, "function": "<module>", "code": "print(1/0)"}], "error": {"errorType": "ZeroDivisionError", "message": "division by zero"}, "relatedErrors": [{"snippet": "Traceback (most recent call last):\n    File \"main.py\", line 10, in <module>\n        result = divide(5, 0)\n    File \"main.py\", line 6, in divide\n        return a / b\n    ZeroDivisionError: division by zero", "sourceType": "python_docs", "url": "https://docs.python.org/3/library/exceptions.html#ZeroDivisionError"}, {"snippet": "Traceback (most recent call last):\n    File \"main.py\", line 8, in <module>\n        value = d['missing']\n    KeyError: 'missing'", "sourceType": "python_docs", "url": "https://docs.python.org/3/library/exceptions.html#KeyError"}, {"snippet": "Traceback (most recent call last):\n    File \"main.py\", line 12, in <module>\n        item = my_list[10]\n    IndexError: list index out of range", "sourceType": "user_past_error", "url": ""}], "fixSuggestion": {"summary": "ZeroDivisionError: division by zero", "codeExample": "def divide(a, b):\n    if b == 0:\n        raise ZeroDivisionError('division by zero')\n    return a / b\n\nresult = divide(5, 0)", "references": [{"snippet": "Avoid division by zero in Python.", "sourceType": "documentation", "url": "https://docs.python.org/3/library/exceptions.html#ZeroDivisionError"}]}}}
{"timestamp": "2025-07-20T14:12:38.614510+00:00", "trace": "Traceback (most recent call last):\n  File \"test.py\", line 5, in <module>\n    result = 10 / 0\nZeroDivisionError: division by zero", "result": {"parsedTrace": [{"file": "test.py", "line": 5, "function": "<module>", "code": "result = 10 / 0"}], "error": {"errorType": "ZeroDivisionError", "message": "division by zero"}, "relatedErrors": [{"snippet": "Traceback (most recent call last):\n    File \"main.py\", line 10, in <module>\n        result = divide(5, 0)\n    File \"main.py\", line 6, in divide\n        return a / b\n    ZeroDivisionError: division by zero", "sourceType": "python_docs", "url": "https://docs.python.org/3/library/exceptions.html#ZeroDivisionError"}, {"snippet": "Traceback (most recent call last):\n    File \"main.py\", line 8, in <module>\n        value = d['missing']\n    KeyError: 'missing'", "sourceType": "python_docs", "url": "https://docs.python.org/3/library/exceptions.html#KeyError"}, {"snippet": "Traceback (most recent call last):\n    File \"main.py\", line 12, in <module>\n        item = my_list[10]\n    IndexError: list index out of range", "sourceType": "user_past_error", "url": ""}], "fixSuggestion": {"summary": "An error occurred while processing the fix suggestion.", "codeExample": "", "references": [], "error": "RetryError[<Future at 0x1d95495d450 state=finished raised ResponseError>]"}}}
{"timestamp": "2025-07-20T14:13:15.858568+00:00", "trace": "Traceback (most recent call last):\n  File \"main.py\", line 3, in <module>\n    value = data['key']\nKeyError: 'key'", "result": {"parsedTrace": [{"file": "main.py", "line": 3, "function": "<module>", "code": "value = data['key']"}], "error": {"errorType": "KeyError", "message": "'key'"}, "relatedErrors": [{"snippet": "Traceback (most recent call last):\n    File \"main.py\", line 8, in <module>\n        value = d['missing']\n    KeyError: 'missing'", "sourceType": "python_docs", "url": "https://docs.python.org/3/library/exceptions.html#KeyError"}, {"snippet": "Traceback (most recent call last):\n    File \"main.py\", line 12, in <module>\n        item = my_list[10]\n    IndexError: list index out of range", "sourceType": "user_past_error", "url": ""}, {"snippet": "Traceback (most recent call last):\n    File \"main.py\", line 10, in <module>\n        result = divide(5, 0)\n    File \"main.py\", line 6, in divide\n        return a / b\n    ZeroDivisionError: division by zero", "sourceType": "python_docs", "url": "https://docs.python.org/3/library/exceptions.html#ZeroDivisionError"}], "fixSuggestion": {"summary": "An error occurred while processing the fix suggestion.", "codeExample": "", "references": [], "error": "RetryError[<Future at 0x1d9548fb950 state=finished raised ResponseError>]"}}}
{"timestamp": "2025-07-20T14:15:03.050041+00:00", "trace": "Traceback (most recent call last):\n  File \"app.py\", line 15, in <module>\n    result = my_list[100]\nIndexError: list index out of range", "result": {"parsedTrace": [{"file": "app.py", "line": 15, "function": "<module>", "code": "result = my_list[100]"}], "error": {"errorType": "IndexError", "message": "list index out of range"}, "relatedErrors": [{"snippet": "Traceback (most recent call last):\n    File \"main.py\", line 12, in <module>\n        item = my_list[10]\n    IndexError: list index out of range", "sourceType": "user_past_error", "url": ""}, {"snippet": "Traceback (most recent call last):\n    File \"main.py\", line 8, in <module>\n        value = d['missing']\n    KeyError: 'missing'", "sourceType": "python_docs", "url": "https://docs.python.org/3/library/exceptions.html#KeyError"}, {"snippet": "Traceback (most recent call last):\n    File \"main.py\", line 10, in <module>\n        result = divide(5, 0)\n    File \"main.py\", line 6, in divide\n        return a / b\n    ZeroDivisionError: division by zero", "sourceType": "python_docs", "url": "https://docs.python.org/3/library/exceptions.html#ZeroDivisionError"}], "fixSuggestion": {"summary": "The error 'IndexError: list index out of range' occurs when you try to access an index that is not within the bounds of a list.", "codeExample": "Here is an example where this error might occur:\n```python\nmy_list = [1, 2, 3]\nitem = my_list[3]\n```", "references": [{"snippet": "Always check the length of your list before accessing its elements to avoid this error.", "sourceType": "tutorial", "url": "https://docs.python.org/3/tutorial/errors.html#err-index"}]}}}
